# 错误与异常

在 Golang 中，异常和错误是 2 种截然不同的概念：

- 错误通常指在情理之中发生的情况，它不会停止程序的运行
- 异常通常指在情理之外发生的情况，它会立即停止程序的运行

举个例子：

- 微服务里某一个服务失联后，前 3 次心跳机制没有回应时可以被认为是错误阶段，直到第 4 次心跳仍然没有回应后，就可以从错误阶段提升到异常阶段



# 返回错误

通过内置库 errors 即可定义一个错误，定义完成的错误通常将作为函数最后一个返回值出现。

如下所示：

```
package main

import (
	"errors"
	"fmt"
)

func errFunc() (bool, error) {
	// 若没有错误，返回 nil 即可
	return false, errors.New("this is error")
}

func main() {
	fmt.Printf("err func run start\n")
	isOk, err := errFunc()
	if err != nil {
		fmt.Printf("%#v\n", err.Error())
		// return
	}
	fmt.Printf("%#v\n", isOk)
	fmt.Printf("err func run end\n")
}

// err func run start
// "this is error"
// false
// err func run end
```

通过上面这段代码，可以发现错误并不会影响程序代码的继续运行

# 抛出异常

通过内置函数 panic 即可主动抛出一个异常，程序中异常一旦出现，将会结束运行：

```
package main

import "fmt"

func panicFunc() {
	panic("panic !")
}

func main() {
	fmt.Printf("panic func run start\n")
	panicFunc()
	fmt.Printf("panic func run end\n")
}

// panic func run start
// panic: panic !
```





# 捕获异常

通过内置函数 recover 即可捕获 panic，需要注意的是 recover 只能在 defer 的匿名自执行函数中使用才会生效，并且在定义 recover 时一定要将它放置在 panic 语句的上方才会生效：

```
package main

import "fmt"

func recoverFunc() {
	defer func() {
		err := recover()
		if err != nil {
			fmt.Printf("recover -> %#v\n", err)
		}
	}()
	panic("panic !")
}

func main() {
	fmt.Printf("recover func run start\n")
	recoverFunc()
	fmt.Printf("recover func run end\n")
}

// recover func run start
// recover -> "panic !"
// recover func run end
```

注意，异常与捕获不能随意滥用，除非程序运行时出现不可逆转的情况下才能进行使用，否则使用错误即可。

# try catch

Golang 并未提供 try catch 关键字，但是我们可以使用 panic 和 recover 来实现类似 try catch 的效果：

```
package main

import "fmt"

func Try(function func(), callback func(any)) {
	defer func() {
		err := recover()
		if err != nil {
			callback(err)
		}
	}()
	function()
}

func run() {
	panic("panic !")
}

func main() {
	Try(
		// 正常逻辑
		run,
		// 发生错误后
		func(err any) {
			fmt.Printf("%#v\n", err)
		},
	)
}

// "panic !"
```



# 如何抉择

Golang 将错误和异常分开，其本意就想让开发人员尽量使用错误而不使用异常。

因此在程序尚未遇见不可恢复的情况时，尽量不要使用 painc 主动抛出异常，而是让函数返回错误即可。
